Workbook
Name Base: Produccion_2026!$A$1:$ND$44
Name Base: Produccion!$A$1:$NC$40
Name Datos: Produccion!$B$2:$NI$40
Name Datos2: Produccion_2026!$B$6:$NE$44
Name Datos3Compras: Produccion_2026!$B$2:$ND$44
Name DatosVentas: Ventas_Des!$C$1:$BB$42
Name Fechas: Produccion!$B$2:$NI$2
Name Fechas2: Produccion_2026!$B$2:$NE$2
Name Meses: 'Semanas 2018-2019'!$AO$2:$AR$13
Name Meses2: 'Semanas 2018-2019'!$AO$16:$AR$27
Name Meses3: 'Semanas 2018-2019'!$AO$30:$AR$41
Name Meses4: 'Semanas 2018-2019'!$AO$44:$AR$55
Name Meses5: 'Semanas 2018-2019'!$AO$58:$AR$69
Name Producto: Produccion!$A:$A
Name Semana21: 'Semanas 2018-2019'!$M$3:$O$55
Name Semana22: 'Semanas 2018-2019'!$Q$3:$S$54
Name Semana23: 'Semanas 2018-2019'!$U$3:$W$54
Name Semana24: 'Semanas 2018-2019'!$Y$3:$AA$54
Name Semana25: 'Semanas 2018-2019'!$AC$3:$AE$54
Name Semana26: 'Semanas 2018-2019'!$AG$3:$AI$54
Name Semanas19: 'Semanas 2018-2019'!$I$3:$K$54
Name SemanasVentas: Ventas_Des!$C$1:$BC$1
Name SemanasVentas2: Ventas_Des2!$C$1:$BC$1

Sheet Produccion
A1: Semanas | C1: 1 | D1: 1 | E1: 1 | F1: 1 | G1: 1 | H1: 1 | I1: 1 | J1: 2 | K1: 2 | L1: 2 | M1: 2 | N1: 2 | O1: 2 | P1: 2 | Q1: 3 | R1: 3 | S1: 3 | T1: 3 | U1: 3 | V1: 3 | W1: 3 | X1: 4 | Y1: 4 | Z1: 4 | AA1: 4 | AB1: 4 | AC1: 4 | AD1: 4 | AE1: 5 | AF1: 5 | AG1: 5 | AH1: 5 | AI1: 5 | AJ1: 5 | AK1: 5 | AL1: 6 | AM1: 6 | AN1: 6 | AO1: 6 | AP1: 6 | AQ1: 6 | AR1: 6 | AS1: 7 | AT1: 7 | AU1: 7 | AV1: 7 | AW1: 7 | AX1: 7 | AY1: 7 | AZ1: 8 | BA1: 8 | BB1: 8 | BC1: 8 | BD1: 8 | BE1: 8 | BF1: 8 | BG1: 9 | BH1: 9 | BI1: 9 | BJ1: 9 | BK1: 9 | BL1: 9 | BM1: 9 | BN1: 10 | BO1: 10 | BP1: 10 | BQ1: 10 | BR1: 10 | BS1: 10 | BT1: 10 | BU1: 11 | BV1: 11 | BW1: 11 | BX1: 11 | BY1: 11 | BZ1: 11 | CA1: 11 | CB1: 12 | CC1: 12 | CD1: 12 | CE1: 12 | CF1: 12 | CG1: 12 | CH1: 12 | CI1: 13 | CJ1: 13 | CK1: 13 | CL1: 13 | CM1: 13 | CN1: 13 | CO1: 13 | CP1: 14 | CQ1: 14 | CR1: 14 | CS1: 14 | CT1: 14 | CU1: 14 | CV1: 14 | CW1: 15 | CX1: 15 | CY1: 15 | CZ1: 15 | DA1: 15 | DB1: 15 | DC1: 15 | DD1: 16 | DE1: 16 | DF1: 16 | DG1: 16 | DH1: 16 | DI1: 16 | DJ1: 16 | DK1: 17 | DL1: 17 | DM1: 17 | DN1: 17 | DO1: 17 | DP1: 17 | DQ1: 17 | DR1: 18 | DS1: 18 | DT1: 18 | DU1: 18 | DV1: 18 | DW1: 18 | DX1: 18 | DY1: 19 | DZ1: 19 | EA1: 19 | EB1: 19 | EC1: 19 | ED1: 19 | EE1: 19 | EF1: 20 | EG1: 20 | EH1: 20 | EI1: 20 | EJ1: 20 | EK1: 20 | EL1: 20 | EM1: 21 | EN1: 21 | EO1: 21 | EP1: 21 | EQ1: 21 | ER1: 21 | ES1: 21 | ET1: 22 | EU1: 22 | EV1: 22 | EW1: 22 | EX1: 22 | EY1: 22 | EZ1: 22 | FA1: 23 | FB1: 23 | FC1: 23 | FD1: 23 | FE1: 23 | FF1: 23 | FG1: 23 | FH1: 24 | FI1: 24 | FJ1: 24 | FK1: 24 | FL1: 24 | FM1: 24 | FN1: 24 | FO1: 25 | FP1: 25 | FQ1: 25 | FR1: 25 | FS1: 25 | FT1: 25 | FU1: 25 | FV1: 26 | FW1: 26 | FX1: 26 | FY1: 26 | FZ1: 26 | GA1: 26 | GB1: 26 | GC1: 27 | GD1: 27 | GE1: 27 | GF1: 27 | GG1: 27 | GH1: 27 | GI1: 27 | GJ1: 28 | GK1: 28 | GL1: 28 | GM1: 28 | GN1: 28 | GO1: 28 | GP1: 28 | GQ1: 29 | GR1: 29 | GS1: 29 | GT1: 29 | GU1: 29 | GV1: 29 | GW1: 29 | GX1: 30 | GY1: 30 | GZ1: 30 | HA1: 30 | HB1: 30 | HC1: 30 | HD1: 30 | HE1: 31 | HF1: 31 | HG1: 31 | HH1: 31 | HI1: 31 | HJ1: 31 | HK1: 31 | HL1: 32 | HM1: 32 | HN1: 32 | HO1: 32 | HP1: 32 | HQ1: 32 | HR1: 32 | HS1: 33 | HT1: 33 | HU1: 33 | HV1: 33 | HW1: 33 | HX1: 33 | HY1: 33 | HZ1: 34 | IA1: 34 | IB1: 34 | IC1: 34 | ID1: 34 | IE1: 34 | IF1: 34 | IG1: 35 | IH1: 35 | II1: 35 | IJ1: 35 | IK1: 35 | IL1: 35 | IM1: 35 | IN1: 36 | IO1: 36 | IP1: 36 | IQ1: 36 | IR1: 36 | IS1: 36 | IT1: 36 | IU1: 37 | IV1: 37 | IW1: 37 | IX1: 37 | IY1: 37 | IZ1: 37 | JA1: 37 | JB1: 38 | JC1: 38 | JD1: 38 | JE1: 38 | JF1: 38 | JG1: 38 | JH1: 38 | JI1: 39 | JJ1: 39 | JK1: 39 | JL1: 39 | JM1: 39 | JN1: 39 | JO1: 39 | JP1: 40 | JQ1: 40 | JR1: 40 | JS1: 40 | JT1: 40 | JU1: 40 | JV1: 40 | JW1: 41 | JX1: 41 | JY1: 41 | JZ1: 41 | KA1: 41 | KB1: 41 | KC1: 41 | KD1: 42 | KE1: 42 | KF1: 42 | KG1: 42 | KH1: 42 | KI1: 42 | KJ1: 42 | KK1: 43 | KL1: 43 | KM1: 43 | KN1: 43 | KO1: 43 | KP1: 43 | KQ1: 43 | KR1: 44 | KS1: 44 | KT1: 44 | KU1: 44 | KV1: 44 | KW1: 44 | KX1: 44 | KY1: 45 | KZ1: 45 | LA1: 45 | LB1: 45 | LC1: 45 | LD1: 45 | LE1: 45 | LF1: 46 | LG1: 46 | LH1: 46 | LI1: 46 | LJ1: 46 | LK1: 46 | LL1: 46 | LM1: 47 | LN1: 47 | LO1: 47 | LP1: 47 | LQ1: 47 | LR1: 47 | LS1: 47 | LT1: 48 | LU1: 48 | LV1: 48 | LW1: 48 | LX1: 48 | LY1: 48 | LZ1: 48 | MA1: 49 | MB1: 49 | MC1: 49 | MD1: 49 | ME1: 49 | MF1: 49 | MG1: 49 | MH1: 50 | MI1: 50 | MJ1: 50 | MK1: 50 | ML1: 50 | MM1: 50 | MN1: 50 | MO1: 51 | MP1: 51 | MQ1: 51 | MR1: 51 | MS1: 51 | MT1: 51 | MU1: 51 | MV1: 52 | MW1: 52 | MX1: 52 | MY1: 52 | MZ1: 52 | NA1: 52 | NB1: 52 | NC1: 53 | ND1: 53 | NE1: 53 | NF1: 53 | NG1: 53 | NH1: 53 | NI1: 53
A2: Fábrica Papayas | B2: 44192 | C2: 44193 | D2: 44194 | E2: 44195 | F2: 44196 | G2: 44197 | H2: 44198 | I2: 44199 | J2: 44200 | K2: 44201 | L2: 44202 | M2: 44203 | N2: 44204 | O2: 44205 | P2: 44206 | Q2: 44207 | R2: 44208 | S2: 44209 | T2: 44210 | U2: 44211 | V2: 44212 | W2: 44213 | X2: 44214 | Y2: 44215 | Z2: 44216 | AA2: 44217 | AB2: 44218 | AC2: 44219 | AD2: 44220 | AE2: 44221 | AF2: 44222 | AG2: 44223 | AH2: 44224 | AI2: 44225 | AJ2: 44226 | AK2: 44227 | AL2: 44228 | AM2: 44229 | AN2: 44230 | AO2: 44231 | AP2: 44232 | AQ2: 44233 | AR2: 44234 | AS2: 44235 | AT2: 44236 | AU2: 44237 | AV2: 44238 | AW2: 44239 | AX2: 44240 | AY2: 44241 | AZ2: 44242 | BA2: 44243 | BB2: 44244 | BC2: 44245 | BD2: 44246 | BE2: 44247 | BF2: 44248 | BG2: 44249 | BH2: 44250 | BI2: 44251 | BJ2: 44252 | BK2: 44253 | BL2: 44254 | BM2: 44255 | BN2: 44256 | BO2: 44257 | BP2: 44258 | BQ2: 44259 | BR2: 44260 | BS2: 44261 | BT2: 44262 | BU2: 44263 | BV2: 44264 | BW2: 44265 | BX2: 44266 | BY2: 44267 | BZ2: 44268 | CA2: 44269 | CB2: 44270 | CC2: 44271 | CD2: 44272 | CE2: 44273 | CF2: 44274 | CG2: 44275 | CH2: 44276 | CI2: 44277 | CJ2: 44278 | CK2: 44279 | CL2: 44280 | CM2: 44281 | CN2: 44282 | CO2: 44283 | CP2: 44284 | CQ2: 44285 | CR2: 44286 | CS2: 44287 | CT2: 44288 | CU2: 44289 | CV2: 44290 | CW2: 44291 | CX2: 44292 | CY2: 44293 | CZ2: 44294 | DA2: 44295 | DB2: 44296 | DC2: 44297 | DD2: 44298 | DE2: 44299 | DF2: 44300 | DG2: 44301 | DH2: 44302 | DI2: 44303 | DJ2: 44304 | DK2: 44305 | DL2: 44306 | DM2: 44307 | DN2: 44308 | DO2: 44309 | DP2: 44310 | DQ2: 44311 | DR2: 44312 | DS2: 44313 | DT2: 44314 | DU2: 44315 | DV2: 44316 | DW2: 44317 | DX2: 44318 | DY2: 44319 | DZ2: 44320 | EA2: 44321 | EB2: 44322 | EC2: 44323 | ED2: 44324 | EE2: 44325 | EF2: 44326 | EG2: 44327 | EH2: 44328 | EI2: 44329 | EJ2: 44330 | EK2: 44331 | EL2: 44332 | EM2: 44333 | EN2: 44334 | EO2: 44335 | EP2: 44336 | EQ2: 44337 | ER2: 44338 | ES2: 44339 | ET2: 44340 | EU2: 44341 | EV2: 44342 | EW2: 44343 | EX2: 44344 | EY2: 44345 | EZ2: 44346 | FA2: 44347 | FB2: 44348 | FC2: 44349 | FD2: 44350 | FE2: 44351 | FF2: 44352 | FG2: 44353 | FH2: 44354 | FI2: 44355 | FJ2: 44356 | FK2: 44357 | FL2: 44358 | FM2: 44359 | FN2: 44360 | FO2: 44361 | FP2: 44362 | FQ2: 44363 | FR2: 44364 | FS2: 44365 | FT2: 44366 | FU2: 44367 | FV2: 44368 | FW2: 44369 | FX2: 44370 | FY2: 44371 | FZ2: 44372 | GA2: 44373 | GB2: 44374 | GC2: 44375 | GD2: 44376 | GE2: 44377 | GF2: 44378 | GG2: 44379 | GH2: 44380 | GI2: 44381 | GJ2: 44382 | GK2: 44383 | GL2: 44384 | GM2: 44385 | GN2: 44386 | GO2: 44387 | GP2: 44388 | GQ2: 44389 | GR2: 44390 | GS2: 44391 | GT2: 44392 | GU2: 44393 | GV2: 44394 | GW2: 44395 | GX2: 44396 | GY2: 44397 | GZ2: 44398 | HA2: 44399 | HB2: 44400 | HC2: 44401 | HD2: 44402 | HE2: 44403 | HF2: 44404 | HG2: 44405 | HH2: 44406 | HI2: 44407 | HJ2: 44408 | HK2: 44409 | HL2: 44410 | HM2: 44411 | HN2: 44412 | HO2: 44413 | HP2: 44414 | HQ2: 44415 | HR2: 44416 | HS2: 44417 | HT2: 44418 | HU2: 44419 | HV2: 44420 | HW2: 44421 | HX2: 44422 | HY2: 44423 | HZ2: 44424 | IA2: 44425 | IB2: 44426 | IC2: 44427 | ID2: 44428 | IE2: 44429 | IF2: 44430 | IG2: 44431 | IH2: 44432 | II2: 44433 | IJ2: 44434 | IK2: 44435 | IL2: 44436 | IM2: 44437 | IN2: 44438 | IO2: 44439 | IP2: 44440 | IQ2: 44441 | IR2: 44442 | IS2: 44443 | IT2: 44444 | IU2: 44445 | IV2: 44446 | IW2: 44447 | IX2: 44448 | IY2: 44449 | IZ2: 44450 | JA2: 44451 | JB2: 44452 | JC2: 44453 | JD2: 44454 | JE2: 44455 | JF2: 44456 | JG2: 44457 | JH2: 44458 | JI2: 44459 | JJ2: 44460 | JK2: 44461 | JL2: 44462 | JM2: 44463 | JN2: 44464 | JO2: 44465 | JP2: 44466 | JQ2: 44467 | JR2: 44468 | JS2: 44469 | JT2: 44470 | JU2: 44471 | JV2: 44472 | JW2: 44473 | JX2: 44474 | JY2: 44475 | JZ2: 44476 | KA2: 44477 | KB2: 44478 | KC2: 44479 | KD2: 44480 | KE2: 44481 | KF2: 44482 | KG2: 44483 | KH2: 44484 | KI2: 44485 | KJ2: 44486 | KK2: 44487 | KL2: 44488 | KM2: 44489 | KN2: 44490 | KO2: 44491 | KP2: 44492 | KQ2: 44493 | KR2: 44494 | KS2: 44495 | KT2: 44496 | KU2: 44497 | KV2: 44498 | KW2: 44499 | KX2: 44500 | KY2: 44501 | KZ2: 44502 | LA2: 44503 | LB2: 44504 | LC2: 44505 | LD2: 44506 | LE2: 44507 | LF2: 44508 | LG2: 44509 | LH2: 44510 | LI2: 44511 | LJ2: 44512 | LK2: 44513 | LL2: 44514 | LM2: 44515 | LN2: 44516 | LO2: 44517 | LP2: 44518 | LQ2: 44519 | LR2: 44520 | LS2: 44521 | LT2: 44522 | LU2: 44523 | LV2: 44524 | LW2: 44525 | LX2: 44526 | LY2: 44527 | LZ2: 44528 | MA2: 44529 | MB2: 44530 | MC2: 44531 | MD2: 44532 | ME2: 44533 | MF2: 44534 | MG2: 44535 | MH2: 44536 | MI2: 44537 | MJ2: 44538 | MK2: 44539 | ML2: 44540 | MM2: 44541 | MN2: 44542 | MO2: 44543 | MP2: 44544 | MQ2: 44545 | MR2: 44546 | MS2: 44547 | MT2: 44548 | MU2: 44549 | MV2: 44550 | MW2: 44551 | MX2: 44552 | MY2: 44553 | MZ2: 44554 | NA2: 44555 | NB2: 44556 | NC2: 44557 | ND2: 44558 | NE2: 44559 | NF2: 44560 | NG2: 44561 | NH2: 44562 | NI2: 44563
A3: Stock Materia prima de huerto (Kgs) | C3: =+B3+B4-B5-B6-B7 -> 0 | D3: =+C3+C4-C5-C6-C7 -> 1511 | E3: =+D3+D4-D5-D6-D7 -> 896 | F3: =+E3+E4-E5-E6-E7 -> -30 | G3: =+F3+F4-F5-F6-F7 -> -30 | H3: =+G3+G4-G5-G6-G7 -> -30 | I3: =+H3+H4-H5-H6-H7 -> -30 | J3: =+I3+I4-I5-I6-I7 -> -30 | ... EW3: =+EV3+EV4-EV5-EV6-EV7 -> 0 | EX3: 19 | EY3: 19 | EZ3: 19 | FA3: 19 | FB3: =+FA3+FA4-FA5-FA6-FA7 -> 706 | FC3: =+FB3+FB4-FB5-FB6-FB7 -> 948 | FD3: =+FC3+FC4-FC5-FC6-FC7 -> 896 | FE3: =+FD3+FD4-FD5-FD6-FD7 -> 746 | FF3: =+FE3+FE4-FE5-FE6-FE7 -> 281 | FG3: =+FF3+FF4-FF5-FF6-FF7 -> 281 | FH3: =+FG3+FG4-FG5-FG6-FG7 -> 281 | FI3: =+FH3+FH4-FH5-FH6-FH7 -> 1065 | ... FM3: =+FL3+FL4-FL5-FL6-FL7 -> 281 | FN3: 200 | FO3: =+FN3+FN4-FN5-FN6-FN7 -> 200 | FP3: =+FO3+FO4-FO5-FO6-FO7 -> 893 | FQ3: =+FP3+FP4-FP5-FP6-FP7 -> 1070 | FR3: =+FQ3+FQ4-FQ5-FQ6-FQ7 -> 1488 | FS3: =+FR3+FR4-FR5-FR6-FR7 -> 1005 | FT3: =+FS3+FS4-FS5-FS6-FS7 -> 249 | FU3: =+FT3+FT4-FT5-FT6-FT7 -> 249 | FV3: =+FU3+FU4-FU5-FU6-FU7 -> 249 | ... FX3: =+FW3+FW4-FW5-FW6-FW7 -> 1116 | FY3: 894 | FZ3: 758 | GA3: =+FZ3+FZ4-FZ5-FZ6-FZ7 -> 528 | GB3: =+GA3+GA4-GA5-GA6-GA7 -> 528 | GC3: =+GB3+GB4-GB5-GB6-GB7 -> 528 | GD3: =+GC3+GC4-GC5-GC6-GC7 -> 528 | GE3: =+GD3+GD4-GD5-GD6-GD7 -> 1870 | GF3: =+GE3+GE4-GE5-GE6-GE7 -> 2450 | GG3: =+GF3+GF4-GF5-GF6-GF7 -> 2456 | GH3: =+GG3+GG4-GG5-GG6-GG7 -> 1638 | ... NI3: =+NH3+NH4-NH5-NH6-NH7 -> 1029
A4: Materia prima de huerto (Kgs) | C4: 1511 | D4: 1119 | E4: 667 | J4: 876 | K4: 1199 | L4: 615 | M4: 597 | Q4: 930 | R4: 740 | S4: 879 | T4: 315 | X4: 1371 | Y4: 1327 | Z4: 691 | AE4: 1263 | AF4: 769 | AG4: 1036 | AH4: 237 | AL4: 1338 | AM4: 1190 | AN4: 737 | AQ4: 489 | AS4: 1292 | AT4: 894 | AU4: 877 | AV4: 492 | AZ4: 1422 | BA4: 1767 | BB4: 1044 | BG4: 1535 | BH4: 986 | BI4: 559 | BJ4: 408 | BK4: 237 | BN4: 1380 | BO4: 607 | BP4: 831 | BQ4: 596 | BR4: 1014 | BU4: 1800 | BV4: 1074 | BW4: 1057 | CB4: 1387 | CC4: 1348 | CD4: 814 | CI4: 1340 | CJ4: 1315 | CK4: 780 | CP4: 1433 | CQ4: 997 | CR4: 134 | CW4: 1104 | CX4: 1011 | CY4: 787 | CZ4: 676 | DD4: 1195 | DE4: 808 | DI4: 257 | DK4: 1186 | DL4: 379 | DS4: 1192 | DT4: 574 | DU4: 346 | DY4: 811 | DZ4: 373 | EA4: 282 | EF4: 736 | EG4: 446 | EH4: 204 | EM4: 525 | EN4: 553 | EO4: 67 | EW4: 116 | FA4: 687 | FB4: 653 | FC4: 420 | FD4: 455 | FH4: 784 | FI4: 565 | FJ4: 290 | FO4: 693 | FP4: 429 | FQ4: 700 | FW4: 867 | FX4: 206 | FY4: 436 | FZ4: 300 | GD4: 1342 | GE4: 1426 | GF4: 580 | GH4: 600 | GJ4: 1209 | GM4: 390 | GQ4: 1040 | GS4: 795 | GX4: 756 | GY4: 400 | GZ4: 776 | HF4: 1222 | HG4: 926 | HH4: 734 | HI4: 495 | HL4: 1380 | HM4: 782 | HN4: 1203 | HO4: 1020 | HP4: 1015 | HS4: 1109 | HT4: 623 | HU4: 989 | HV4: 691 | HW4: 53 | HX4: 630 | HZ4: 1312 | IA4: 1831 | IB4: 691 | IC4: 1091 | IG4: 1860 | IH4: 1000 | II4: 1491 | IJ4: 1218 | IL4: 606 | IN4: 1376 | IO4: 1266 | IP4: 1433 | IQ4: 1327 | IU4: 1141 | IV4: 604 | IW4: 1337 | IX4: 1059 | IY4: 992 | IZ4: 556 | JB4: 1048 | JC4: 730 | JI4: 1680 | JJ4: 1200 | JK4: 1522 | JL4: 1211 | JQ4: 1746 | JR4: 1018 | JS4: 879 | JW4: 1548 | JX4: 1012 | JY4: 876 | JZ4: 761 | KE4: 1551 | KF4: 1519 | KG4: 1400 | KH4: 551 | KK4: 1388 | KL4: 851 | KM4: 857 | KN4: 222 | KR4: 1271 | KS4: 1025 | KT4: 1124 | KU4: 239 | KZ4: 1474 | LA4: 902 | LB4: 632 | LC4: 1126 | LF4: 1132 | LG4: 791 | LH4: 649 | LI4: 815 | LM4: 1578 | LN4: 874 | LO4: 1166 | LP4: 790 | LT4: 1320 | LU4: 1092 | LV4: 760 | LW4: 722 | LX4: 594 | MA4: 1366 | MB4: 896 | MC4: 953 | MD4: 348 | MH4: 1324 | MI4: 855 | MK4: 1146 | MO4: 1274 | MP4: 983 | MQ4: 921 | MV4: 1183 | MW4: 922 | MX4: 1459 | NC4: 1465 | ND4: 1130 | NE4: 1031 | NF4: 388
A5: Materia prima Elaborada (Kgs) | D5: 644 | E5: 410 | K5: 501 | L5: 157 | M5: 726 | N5: 612 | R5: 500 | S5: 503 | U5: 437 | X5: 0 | Y5: 408 | Z5: 808 | AB5: 320 | AF5: 609 | AH5: 645 | AM5: 593 | AN5: 598 | AP5: 599 | AT5: 474 | AU5: 495 | AV5: 468 | AW5: 345 | BA5: 521 | BB5: 1019 | BD5: 510 | BH5: 367 | BI5: 780 | BJ5: 338 | BK5: 260 | BN5: 237 | BO5: 730 | BP5: 364 | BR5: 694 | BU5: 476 | BV5: 450 | BW5: 687 | BX5: 1052 | CC5: 704 | CD5: 1027 | CF5: 345 | CJ5: 415 | CK5: 854 | CL5: 911 | CP5: 204 | CQ5: 378 | CR5: 1103 | CS5: 343 | CX5: 512 | CY5: 605 | CZ5: 635 | DA5: 1358 | DE5: 811 | DF5: 411 | DK5: 241 | DL5: 854 | DM5: 486 | DO5: 241 | DT5: 822 | DU5: 805 | DV5: 264 | DZ5: 804 | EB5: 522 | EG5: 546 | EH5: 514 | EI5: 20 | EJ5: 393 | EN5: 400 | EO5: 212 | EP5: 505 | EU5: 154 | EX5: 97 | FB5: 394 | FC5: 463 | FD5: 605 | FE5: 458 | FI5: 620 | FJ5: 552 | FL5: 454 | FP5: 252 | FQ5: 282 | FR5: 483 | FS5: 756 | FX5: 497 | FY5: 572 | FZ5: 516 | GE5: 846 | GF5: 560 | GG5: 790 | GJ5: 596 | GK5: 1105 | GM5: 666 | GN5: 416 | GQ5: 499 | GR5: 480 | GT5: 816 | GX5: 378 | GY5: 453 | GZ5: 336 | HA5: 516 | HB5: 334 | HF5: 700 | HG5: 502 | HH5: 703 | HI5: 1054 | HL5: 370 | HM5: 991 | HN5: 367 | HO5: 630 | HP5: 524 | HS5: 1027 | HT5: 923 | HU5: 967 | HV5: 895 | HW5: 1254 | HZ5: 926 | IA5: 800 | IB5: 1062 | IC5: 1053 | ID5: 655 | IG5: 1113 | IH5: 793 | II5: 993 | IJ5: 930 | IK5: 629 | IN5: 1093 | IO5: 1117 | IP5: 888 | IQ5: 1058 | IR5: 945 | IU5: 763 | IV5: 889 | IW5: 905 | IX5: 998 | IY5: 1101 | IZ5: 749 | JB5: 1050 | JC5: 900 | JD5: 1220 | JE5: 230 | JI5: 1239 | JJ5: 778 | JK5: 1126 | JL5: 866 | JM5: 738 | JN5: 1304 | JP5: 903 | JQ5: 599 | JR5: 808 | JS5: 809 | JT5: 756 | JW5: 852 | JX5: 927 | JY5: 680 | JZ5: 1219 | KA5: 305 | KE5: 900 | KF5: 496 | KG5: 800 | KH5: 930 | KK5: 1357 | KL5: 829 | KM5: 807 | KN5: 900 | KO5: 893 | KR5: 1275 | KS5: 975 | KT5: 870 | KU5: 815 | KV5: 605 | KZ5: 370 | LA5: 863 | LB5: 637 | LC5: 890 | LF5: 700 | LG5: 776 | LH5: 1114 | LI5: 578 | LJ5: 754 | LN5: 1038 | LO5: 843 | LP5: 527 | LQ5: 1175 | LT5: 800 | LU5: 940 | LV5: 1074 | LW5: 400 | LX5: 828 | MA5: 531 | MB5: 1209 | MC5: 678 | MD5: 998 | ME5: 777 | MH5: 494 | MI5: 777 | MK5: 1269 | ML5: 812 | MO5: 196 | MP5: 515 | MQ5: 500 | MR5: 1074 | MV5: 786 | MW5: 691 | MX5: 613 | MY5: 765 | MZ5: 639 | NC5: 369 | ND5: 853 | NE5: 682 | NF5: 1243 | NG5: 495
A6: descarte | E6: 26 | L6: 12 | M6: 30 | Z6: 28 | AF6: 43 | AH6: 21 | AM6: 9 | AP6: 92 | BD6: 55 | BJ6: 28 | BR6: 32 | BX6: 137 | CC6: 37 | CL6: 16 | CP6: 18 | CS6: 16 | CX6: 12 | DA6: 38 | DE6: 38 | DF6: 8 | DT6: 39 | DU6: 17 | DV6: 5 | DZ6: 12 | EB6: 18 | EG6: 12 | EJ6: 6 | EU6: 9 | FB6: 17 | FC6: 9 | FE6: 7 | FL6: 13 | FX6: 14 | FZ6: 14 | GF6: 14 | GG6: 28 | GJ6: 78 | GK6: 41 | GM6: 40 | GN6: 18 | GQ6: 57 | GR6: 37 | GT6: 15 | GX6: 7 | GY6: 22 | GZ6: 14 | HG6: 6 | HH6: 12 | HI6: 18 | HM6: 63 | HS6: 214 | HT6: 98 | HU6: 108 | HW6: 25 | HZ6: 110 | IB6: 27 | IC6: 68 | IG6: 267 | II6: 17 | IN6: 93 | IO6: 8 | IQ6: 90 | IR6: 39 | IU6: 105 | IW6: 135 | JB6: 135 | JC6: 64 | JD6: 105 | JI6: 21 | JJ6: 17 | KK6: 37 | KM6: 23 | KR6: 43 | KT6: 13 | KZ6: 5 | LF6: 16 | LN6: 16 | LQ6: 11 | LT6: 16 | LW6: 13 | MA6: 16 | MH6: 16 | MQ6: 13 | MR6: 16 | MV6: 15 | MX6: 15 | NC6: 10 | ND6: 17 | NE6: 10 | NF6: 15
A7: venta descarte por calibre | D7: 1090 | E7: 1157 | K7: 484 | M7: 675 | Q7: 282 | R7: 304 | S7: 447 | T7: 481 | Y7: 662 | Z7: 893 | AA7: 270 | AF7: 512 | AG7: 403 | AH7: 470 | AM7: 752 | AN7: 886 | AO7: 338 | AT7: 763 | AU7: 789 | AV7: 710 | BA7: 617 | BB7: 699 | BC7: 812 | BH7: 458 | BI7: 469 | BJ7: 212 | BK7: 576 | BN7: 36 | BO7: 556 | BP7: 295 | BQ7: 708 | BR7: 530 | BW7: 1462 | CB7: 32 | CC7: 654 | CD7: 900 | CL7: 1017 | CR7: 593 | CX7: 303 | DF7: 981 | IO7: 117 | KO7: 203 | KS7: 186 | LC7: 351 | LH7: 214 | LV7: 441 | MC7: 248 | MH7: 0 | MK7: 271 | MQ7: 205 | MX7: 186
A9: Papaya congelada | C9: 400 | D9: 100 | E9: 110 | J9: 270 | L9: 280 | M9: 80 | N9: 100 | Q9: 400 | T9: 330 | U9: 100 | X9: 450 | AA9: 480 | AB9: 238 | AG9: 400 | AI9: 410 | AM9: 60 | AN9: 60 | AO9: 400 | AP9: 100 | AS9: 400 | AT9: 450 | AU9: 200 | AV9: 160 | AW9: 260 | AX9: 300 | AZ9: 400 | BB9: 120 | BC9: 500 | BD9: 240 | BG9: 250 | BH9: 400 | BI9: 400 | BJ9: 400 | BK9: 300 | BN9: 400 | BO9: 350 | BP9: 350 | BQ9: 500 | BV9: 300 | BY9: 100 | CB9: 500 | CE9: 500 | CF9: 400 | CM9: 400 | CP9: 40 | CS9: 240 | DG9: 380 | DH9: 150 | DK9: 250 | DO9: 210 | DY9: 300 | EF9: 270 | EI9: 250 | EM9: 200 | EO9: 300 | ET9: 300 | EU9: 80 | EV9: 150 | EW9: 230 | FC9: 80 | FH9: 300 | FO9: 400 | FW9: 338 | GD9: 300 | GL9: 500 | GN9: 300 | GR9: 70 | GS9: 550 | GT9: 80 | GX9: 80 | GY9: 200 | GZ9: 300 | HB9: 40 | HE9: 220 | HH9: 70 | HL9: 130 | HN9: 155 | HO9: 100 | HP9: 150 | HS9: 40 | HV9: 120 | HW9: 250 | HZ9: 260 | IA9: 347 | IB9: 259 | ID9: 261 | IH9: 400 | IK9: 200 | IN9: 20 | IO9: 20 | IQ9: 174 | IU9: 300 | IV9: 278 | IW9: 298 | IX9: 40 | JB9: 400 | JC9: 350 | JL9: 400 | JP9: 450 | JQ9: 400 | JS9: 403 | JX9: 184 | JY9: 400 | KA9: 200 | KE9: 0 | KF9: 200 | KG9: 120 | KL9: 420 | KM9: 360 | KO9: 280 | KS9: 287 | KU9: 215 | KV9: 80 | KZ9: 300 | LF9: 300 | LH9: 80 | LJ9: 80 | LM9: 650 | LN9: 220 | LO9: 286 | LP9: 220 | LU9: 322 | LW9: 320 | LX9: 170 | MA9: 215 | MC9: 213 | MH9: 420 | MI9: 135 | ML9: 215 | MO9: 230 | MP9: 230 | MQ9: 185 | MS9: 410 | MV9: 160 | MW9: 160 | MX9: 340 | MY9: 204 | NC9: 340 | ND9: 88 | NF9: 110
A10: Papaya directa | D10: 70 | AM10: 40 | AN10: 40 | AP10: 55 | EJ10: 40 | GQ10: 120 | GR10: 20 | GX10: 50 | HB10: 63 | HF10: 80 | HH10: 80 | HL10: 125 | HS10: 60 | HZ10: 77 | ID10: 30 | IJ10: 200 | IN10: 73 | IO10: 112 | IP10: 230 | IV10: 100 | JB10: 40 | JC10: 50 | JJ10: 150 | JK10: 0 | JL10: 35 | JW10: 200 | JX10: 50 | KE10: 150 | KH10: 40 | KM10: 60 | KZ10: 70 | MA10: 115 | MH10: 93 | MO10: 81 | MP10: 40 | NE10: 80
A11: Nectar 250cc | B11: 1846 | E11: 1276 | J11: 2204 | Q11: 1304 | AA11: 2851 | AG11: 1172 | AI11: 1154 | AN11: 1163 | AO11: 1227 | AV11: 1616 | AW11: 623 | AZ11: 2190 | BC11: 1200 | BH11: 126 | BI11: 1638 | BQ11: 4177 | CE11: 1224 | CF11: 1140 | CM11: 2200 | DK11: 2240 | EF11: 3240 | EW11: 2279 | FC11: 232 | FH11: 3133 | GN11: 3316 | GS11: 2953 | GZ11: 1211 | HB11: 1469 | HN11: 1663 | HO11: 1049 | HP11: 1104 | HS11: 1094 | HV11: 1268 | IA11: 1737 | ID11: 1060 | IH11: 1658 | IK11: 2720 | IO11: 652 | IP11: 1611 | IV11: 1682 | IX11: 553 | JC11: 2583 | JL11: 2254 | JQ11: 1132 | JS11: 2310 | JW11: 2885 | KG11: 1685 | KM11: 4668 | KS11: 1080 | KU11: 1053 | KZ11: 3963 | LF11: 63 | LH11: 580 | LJ11: 1134 | LW11: 4402 | MH11: 460 | ML11: 2772 | MO11: 4462 | NC11: 1883 | NF11: 553
A12: Nectar 250cc light | B12: 541 | D12: 935 | N12: 515 | T12: 659 | AB12: 668 | AM12: 388 | AU12: 929 | AZ12: 262 | BD12: 1098 | BK12: 240 | BP12: 2491 | EU12: 996 | FO12: 36 | GD12: 1345 | GX12: 693 | HN12: 176 | HP12: 520 | IB12: 643 | IN12: 500 | IQ12: 1305 | IW12: 1597 | KH12: 521 | KV12: 1002 | LH12: 1070 | LO12: 0 | LX12: 2136 | MQ12: 2524 | NE12: 513
A13: Nectar 1 lt | B13: 1148 | C13: 1223 | K13: 174 | L13: 760 | M13: 290 | Q13: 970 | U13: 284 | X13: 864 | AA13: 829 | AG13: 905 | AI13: 1023 | AO13: 950 | AP13: 288 | AS13: 1104 | AT13: 840 | AW13: 576 | AX13: 865 | BB13: 325 | BC13: 1050 | BG13: 586 | BH13: 1170 | BJ13: 1227 | BN13: 1003 | BV13: 682 | BY13: 283 | CB13: 1407 | CE13: 1103 | CM13: 312 | CS13: 807 | DG13: 1161 | DR13: 1020 | DY13: 624 | EJ13: 142 | EM13: 582 | EO13: 785 | ET13: 747 | FC13: 224 | FO13: 1046 | FW13: 894 | GL13: 1498 | GQ13: 432 | GR13: 371 | GS13: 1045 | GT13: 299 | GY13: 591 | GZ13: 527 | HE13: 583 | HF13: 286 | HH13: 532 | HL13: 837 | HW13: 468 | HZ13: 1328 | IA13: 820 | ID13: 600 | IH13: 1202 | IJ13: 837 | IO13: 424 | IP13: 580 | IU13: 878 | IV13: 1026 | JB13: 1582 | JC13: 354 | JJ13: 421 | JK13: 0 | JL13: 748 | JP13: 1448 | JS13: 791 | JX13: 740 | JY13: 1307 | KE13: 583 | KF13: 847 | KL13: 1477 | KO13: 1014 | KS13: 747 | KU13: 533 | LF13: 1005 | LM13: 1931 | LN13: 0 | LO13: 1000 | LP13: 839 | LQ13: 0 | MA13: 1163 | MC13: 806 | MH13: 1489 | MS13: 1462 | MV13: 591 | MW13: 547 | MX13: 1163 | MY13: 137 | NC13: 855 | NF13: 133
A14: Nectar 1 lt ligth | B14: 307 | D14: 264 | J14: 131 | N14: 121 | T14: 665 | AB14: 350 | AM14: 160 | AP14: 126 | AT14: 386 | AU14: 302 | AZ14: 483 | BD14: 261 | BI14: 125 | BJ14: 360 | BK14: 321 | BO14: 620 | CF14: 400 | CP14: 131 | DH14: 400 | DO14: 537 | EI14: 532 | EV14: 396 | GD14: 469 | GX14: 283 | HL14: 87 | HW14: 251 | IB14: 657 | IK14: 135 | IN14: 142 | IQ14: 343 | IW14: 670 | JQ14: 829 | KA14: 533 | KB14: 0 | KU14: 291 | KZ14: 51 | LN14: 636 | LT14: 0 | LU14: 1052 | MI14: 422 | MP14: 823 | MY14: 382 | ND14: 193 | NE14: 124
A15: Papaya congelada | L15: 29 | N15: 20 | R15: 25 | X15: 59 | AG15: 60 | AM15: 55 | AN15: 25 | AU15: 20 | AV15: 42 | AZ15: 55 | BC15: 78 | BH15: 39 | BJ15: 39 | BK15: 52 | BO15: 70 | BP15: 63 | BQ15: 81 | BU15: 101 | BW15: 50 | CF15: 97 | CP15: 41 | CQ15: 76 | DG15: 60 | DO15: 20 | EA15: 100 | EU15: 86 | EX15: 71 | HN15: 44 | HP15: 47 | IX15: 152 | JR15: 146 | KA15: 70 | KM15: 46 | KR15: 45 | KT15: 174 | LJ15: 46 | LT15: 70 | LV15: 70 | MB15: 155 | MD15: 85 | MR15: 76 | MS15: 55
A16: Papaya directa | K16: 76 | L16: 19 | M16: 159 | N16: 84 | R16: 115 | S16: 91 | U16: 92 | Y16: 83 | Z16: 171 | AB16: 22 | AF16: 122 | AH16: 111 | AM16: 128 | AN16: 105 | AP16: 78 | AT16: 126 | AU16: 123 | AV16: 108 | AW16: 62 | BA16: 112 | BB16: 164 | BH16: 35 | BI16: 118 | BJ16: 52 | BK16: 36 | BO16: 117 | BP16: 90 | BR16: 145 | BU16: 98 | BV16: 101 | BW16: 136 | BY16: 153 | CC16: 154 | CD16: 152 | CF16: 39 | CJ16: 110 | CK16: 194 | CL16: 66 | CP16: 99 | CQ16: 90 | CR16: 222 | CS16: 89 | CX16: 103 | CY16: 141 | CZ16: 140 | DA16: 154 | DE16: 227 | DF16: 133 | DL16: 131 | DM16: 104 | DT16: 131 | DU16: 45 | DV16: 53 | DZ16: 76 | EB16: 56 | EG16: 89 | EH16: 49 | EJ16: 68 | EN16: 41 | EP16: 81 | EU16: 23 | EX16: 20 | FB16: 75 | FC16: 100 | FD16: 93 | FE16: 89 | FI16: 121 | FJ16: 57 | FL16: 101 | FO16: 86 | FP16: 77 | FQ16: 20 | FR16: 100 | FS16: 84 | FX16: 140 | FY16: 118 | FZ16: 143 | GE16: 97 | GF16: 137 | GG16: 84 | GJ16: 128 | GK16: 121 | GM16: 95 | GN16: 60 | GQ16: 48 | GR16: 53 | GT16: 99 | GX16: 66 | GY16: 65 | GZ16: 30 | HA16: 74 | HB16: 75 | HF16: 120 | HG16: 118 | HI16: 150 | HM16: 119 | HN16: 20 | HO16: 161 | HP16: 102 | HS16: 56 | HT16: 185 | HU16: 127 | HV16: 86 | HW16: 97 | HZ16: 110 | IA16: 257 | IB16: 86 | IC16: 55 | IG16: 239 | II16: 360 | IK16: 121 | IN16: 35 | IO16: 328 | IQ16: 114 | IU16: 98 | IW16: 57 | IY16: 137 | JC16: 92 | JD16: 224 | JJ16: 34 | JK16: 137 | JL16: 0 | JM16: 102 | JP16: 65 | JQ16: 39 | JR16: 108 | JT16: 144 | JX16: 111 | JZ16: 144 | KA16: 88 | KF16: 122 | KG16: 166 | KH16: 126 | KL16: 80 | KM16: 110 | KN16: 32 | KO16: 130 | KR16: 67 | KS16: 95 | KT16: 67 | KU16: 113 | LA16: 106 | LC16: 121 | LF16: 52 | LG16: 125 | LH16: 95 | LI16: 126 | LJ16: 97 | LN16: 138 | LP16: 83 | LQ16: 156 | LT16: 139 | LV16: 148 | LX16: 128 | MB16: 190 | MD16: 159 | MH16: 45 | MI16: 95 | MK16: 108 | ML16: 89 | MP16: 60 | MQ16: 41 | MR16: 135 | MV16: 65 | MW16: 72 | MX16: 113 | MY16: 213 | ND16: 164 | NF16: 256
A17: Papaya Jugo 1 Kg | B17: 622 | D17: 278 | E17: 170 | K17: 124 | L17: 6 | M17: 277 | N17: 152 | R17: 184 | S17: 136 | U17: 159 | Y17: 149 | Z17: 320 | AB17: 86 | AF17: 214 | AH17: 200 | AM17: 242 | AN17: 198 | AP17: 144 | AT17: 173 | AU17: 140 | AV17: 144 | AW17: 115 | BA17: 215 | BB17: 314 | BD17: 219 | BH17: 69 | BI17: 224 | BJ17: 127 | BK17: 57 | BO17: 255 | BP17: 171 | BR17: 281 | BU17: 186 | BV17: 192 | BW17: 262 | BY17: 295 | CC17: 230 | CD17: 255 | CF17: 64 | CJ17: 181 | CK17: 341 | CL17: 110 | CP17: 65 | CQ17: 148 | CR17: 405 | CS17: 162 | CX17: 178 | CY17: 263 | CZ17: 253 | DA17: 289 | DE17: 318 | DF17: 140 | DL17: 222 | DM17: 162 | DO17: 80 | DT17: 197 | DU17: 79 | DV17: 90 | DZ17: 130 | EB17: 34 | EG17: 109 | EH17: 75 | EJ17: 94 | EN17: 61 | EP17: 122 | EU17: 26 | EX17: 25 | FB17: 101 | FC17: 159 | FD17: 151 | FE17: 149 | FI17: 173 | FJ17: 89 | FL17: 172 | FO17: 152 | FP17: 115 | FQ17: 19 | FR17: 168 | FS17: 96 | FX17: 204 | FY17: 46 | FZ17: 211 | GE17: 178 | GF17: 257 | GG17: 102 | GJ17: 217 | GK17: 188 | GM17: 137 | GN17: 72 | GQ17: 75 | GR17: 95 | GT17: 176 | GX17: 115 | GY17: 106 | GZ17: 50 | HA17: 130 | HB17: 133 | HF17: 224 | HG17: 220 | HI17: 268 | HM17: 216 | HO17: 263 | HP17: 161 | HS17: 96 | HT17: 297 | HU17: 142 | HV17: 144 | HW17: 144 | HZ17: 111 | IA17: 289 | IB17: 147 | IC17: 54 | IG17: 415 | II17: 413 | IK17: 208 | IN17: 60 | IO17: 461 | IQ17: 191 | IU17: 165 | IW17: 101 | IY17: 162 | JC17: 144 | JD17: 216 | JJ17: 60 | JK17: 236 | JL17: 0 | JM17: 177 | JP17: 111 | JQ17: 58 | JR17: 191 | JT17: 273 | JX17: 210 | JZ17: 267 | KA17: 146 | KB17: 0 | KF17: 124 | KG17: 181 | KH17: 171 | KL17: 106 | KM17: 199 | KN17: 58 | KO17: 240 | KR17: 73 | KS17: 181 | KT17: 90 | KU17: 200 | KV17: 100 | LA17: 190 | LC17: 208 | LF17: 96 | LG17: 124 | LH17: 180 | LI17: 95 | LJ17: 136 | LN17: 261 | LO17: 0 | LP17: 97 | LQ17: 275 | LT17: 134 | LV17: 247 | LX17: 218 | MB17: 308 | MD17: 299 | MH17: 30 | MI17: 139 | MK17: 154 | ML17: 157 | MP17: 120 | MQ17: 72 | MR17: 250 | MV17: 96 | MW17: 125 | MX17: 199 | MY17: 260 | ND17: 270 | NF17: 471
A18: Papaya Jugo 460 grs | B18: 97 | E18: 9 | K18: 34 | L18: 51 | M18: 31 | N18: 13 | R18: 63 | S18: 66 | U18: 35 | Y18: 16 | Z18: 25 | AB18: 14 | AF18: 15 | AH18: 22 | CC18: 110 | CD18: 58 | CJ18: 37 | CK18: 72 | CL18: 16 | CQ18: 41 | CR18: 39 | CZ18: 25 | DE18: 100 | DF18: 9 | DL18: 32 | DM18: 32 | DT18: 17 | DV18: 10 | EB18: 131 | EG18: 117 | EH18: 31 | EJ18: 51 | EN18: 40 | EP18: 48 | EU18: 13 | EX18: 35 | FB18: 51 | FC18: 63 | FD18: 43 | FE18: 11 | FI18: 92 | FJ18: 35 | FL18: 61 | FO18: 11 | FP18: 40 | FQ18: 25 | FR18: 26 | FS18: 91 | FX18: 34 | FY18: 10 | FZ18: 21 | GG18: 101 | GJ18: 45 | GK18: 64 | GM18: 58 | GN18: 48 | GQ18: 12 | GY18: 16 | HO18: 81 | HP18: 29 | HT18: 95 | HU18: 30 | HV18: 23 | HW18: 68 | HZ18: 18 | IA18: 67 | IB18: 16 | IC18: 28 | IG18: 91 | II18: 67 | IK18: 39 | IO18: 65 | IQ18: 75 | IU18: 42 | IW18: 11 | IY18: 27 | JC18: 45 | JK18: 46 | JL18: 0 | JM18: 27 | JP18: 9 | JQ18: 20 | JR18: 15 | JZ18: 36 | KA18: 43 | KB18: 0 | KF18: 34 | KG18: 128 | KH18: 47 | KL18: 60 | KM18: 25 | KO18: 20 | KT18: 71 | KU18: 17 | KV18: 6 | LA18: 21 | LC18: 37 | LG18: 28 | LH18: 0 | LI18: 34 | LP18: 121 | LQ18: 56 | LV18: 82 | LX18: 61 | MB18: 111 | MD18: 20 | MH18: 97 | MI18: 87 | MK18: 127 | ML18: 27 | MP18: 9 | MR18: 17 | MV18: 50 | MW18: 19 | MX18: 35 | ND18: 96 | NF18: 87
A19: Papaya Jugo Cubitos 150gr | B19: 532 | N19: 331 | AV19: 443 | BB19: 241 | BK19: 191 | BP19: 533 | BW19: 566 | DG19: 305 | EA19: 387 | EU19: 307 | FZ19: 516 | IC19: 809 | IY19: 823 | KA19: 211 | KG19: 443 | KR19: 813 | LG19: 136 | MD19: 882 | MS19: 900
A20: Papaya Jugo Cubitos 460gr | B20: 363 | L20: 192 | R20: 77 | X20: 236 | AG20: 258 | AM20: 237 | AN20: 84 | AT20: 138 | AU20: 220 | AV20: 158 | AZ20: 184 | BC20: 259 | BH20: 83 | BJ20: 320 | BK20: 299 | BO20: 206 | BP20: 127 | BQ20: 251 | BU20: 325 | CF20: 224 | CP20: 167 | CQ20: 302 | DE20: 78 | DF20: 201 | DG20: 131 | DO20: 46 | EA20: 210 | EU20: 212 | EX20: 214 | FY20: 338 | HN20: 313 | HP20: 157 | HU20: 153 | HZ20: 192 | IA20: 280 | II20: 441 | IO20: 273 | IX20: 585 | JR20: 544 | KA20: 211 | KF20: 230 | KH20: 194 | KM20: 224 | KT20: 614 | LG20: 122 | LI20: 246 | LJ20: 321 | LT20: 480 | LV20: 222 | MB20: 496 | MR20: 306 | MY20: 305
A21: Papaya congelada | R21: 80 | T21: 120 | AE21: 500 | BA21: 200 | BG21: 200 | BK21: 300 | BR21: 300 | BX21: 400 | CI21: 550 | CJ21: 250 | CQ21: 300 | CW21: 400 | DD21: 350 | DN21: 350 | DV21: 150 | EC21: 150 | EV21: 80 | FA21: 90 | GR21: 70 | HH21: 20 | HO21: 70 | IC21: 250 | IR21: 311 | JD21: 245 | JT21: 377 | KN21: 158 | LI21: 180 | LJ21: 0 | ME21: 20 | ND21: 185 | NE21: 133
A22: Papaya directa | HH22: 80 | KN22: 40 | MV22: 10
A23: Mermelada 1 kg | B23: 340 | R23: 107 | T23: 133 | AE23: 484 | BA23: 146 | BG23: 186 | BK23: 250 | BR23: 111 | BX23: 237 | CI23: 367 | CQ23: 137 | CW23: 393 | DN23: 255 | DV23: 127 | EC23: 127 | EV23: 112 | FA23: 142 | IR23: 192 | JD23: 421 | JT23: 251 | ME23: 5 | ND23: 316
A24: Mermelada 340 | B24: 1582 | AE24: 841 | BA24: 375 | BG24: 280 | BK24: 350 | BR24: 363 | BX24: 617 | CI24: 292 | CJ24: 522 | DD24: 993 | DN24: 347 | DV24: 354 | EC24: 354 | GR24: 335 | HH24: 372 | HO24: 349 | IC24: 1083 | IR24: 709 | JD24: 23 | JT24: 1085 | KN24: 880 | LI24: 810 | LJ24: 0 | ME24: 73 | MV24: 33 | NE24: 599
A26: Papaya Congelada Partida (Kg) | B26: 22251 | D26: 32 | K26: 29 | M26: 83 | N26: 82 | R26: 49 | S26: 57 | U26: 39 | Y26: 39 | Z26: 94 | AB26: 68 | AM26: 40 | AN26: 14 | AU26: 42 | AW26: 60 | BA26: 67 | BB26: 139 | BD26: 33 | BI26: 30 | BJ26: 52 | BO26: 53 | BP26: 71 | BR26: 101 | BU26: 70 | BV26: 38 | BW26: 77 | BX26: 203 | CC26: 65 | CD26: 100 | CF26: 69 | CJ26: 20 | CK26: 50 | CL26: 200 | CR26: 213 | CS26: 30 | CX26: 60 | CY26: 94 | CZ26: 99 | DA26: 256 | DE26: 110 | DF26: 20 | DK26: 42 | DL26: 143 | DM26: 81 | DO26: 48 | DT26: 145 | DU26: 190 | DV26: 50 | DZ26: 175 | EB26: 110 | EG26: 90 | EH26: 117 | EJ26: 47 | EN26: 79 | EO26: 55 | EP26: 96 | EU26: 5 | EX26: 3 | FB26: 33 | FC26: 28 | FD26: 84 | FE26: 79 | FI26: 74 | FJ26: 116 | FL26: 29 | FO26: 121 | FP26: 12 | FQ26: 76 | FR26: 59 | FS26: 157 | FX26: 60 | FY26: 62 | FZ26: 56 | GE26: 200 | GF26: 118 | GG26: 220 | GJ26: 91 | GK26: 283 | GM26: 135 | GN26: 68 | GR26: 116 | GT26: 153 | GY26: 80 | GZ26: 82 | HA26: 104 | HF26: 52 | HG26: 109 | HH26: 67 | HI26: 226 | HM26: 199 | HN26: 122 | HO26: 87 | HP26: 107 | HS26: 234 | HT26: 118 | HU26: 188 | HV26: 180 | HW26: 294 | HZ26: 147 | IA26: 21 | IB26: 291 | IC26: 261 | ID26: 135 | IG26: 184 | IH26: 200 | II26: 15 | IJ26: 225 | IK26: 93 | IN26: 257 | IO26: 61 | IP26: 174 | IQ26: 186 | IR26: 428 | IU26: 220 | IV26: 298 | IW26: 201 | IX26: 440 | IY26: 230 | IZ26: 319 | JB26: 428 | JC26: 161 | JD26: 274 | JE26: 101 | JI26: 494 | JJ26: 102 | JK26: 318 | JL26: 336 | JM26: 212 | JN26: 590 | JP26: 277 | JQ26: 197 | JR26: 220 | JS26: 350 | JT26: 133 | JW26: 184 | JX26: 155 | JY26: 306 | JZ26: 331 | KA26: 37 | KB26: 0 | KE26: 258 | KF26: 101 | KG26: 121 | KH26: 183 | KK26: 608 | KL26: 281 | KM26: 135 | KN26: 249 | KO26: 235 | KR26: 374 | KS26: 293 | KT26: 257 | KU26: 241 | KV26: 260 | KZ26: 84 | LA26: 181 | LB26: 269 | LC26: 230 | LF26: 220 | LG26: 188 | LH26: 369 | LI26: 111 | LJ26: 240 | LN26: 257 | LO26: 390 | LP26: 140 | LQ26: 271 | LT26: 216 | LU26: 385 | LV26: 258 | LW26: 163 | LX26: 175 | MA26: 123 | MB26: 297 | MC26: 307 | MD26: 245 | ME26: 350 | MH26: 60 | MI26: 159 | MK26: 400 | ML26: 238 | MP26: 120 | MQ26: 175 | MR26: 255 | MV26: 139 | MW26: 173 | MX26: 144 | MY26: 147 | MZ26: 285 | NC26: 143 | ND26: 133 | NE26: 234 | NF26: 157 | NG26: 220
A27: Papaya congelada
A28: Papaya directa
A29: Papaya Congelada Cubos (Kg)
A30: Papaya Directa Confites | K30: 38 | L30: 35 | R30: 13 | S30: 26 | U30: 9 | Y30: 12 | Z30: 25 | AM30: 22 | AN30: 10 | AP30: 9 | BA30: 25 | BB30: 30 | BH30: 15 | BI30: 11 | BO30: 22 | BU30: 13 | BV30: 20 | BW30: 27 | CC30: 14 | CD30: 20 | CJ30: 10 | CK30: 12 | DE30: 15 | DF30: 10 | DK30: 48 | DL30: 33 | DM30: 10 | DT30: 48 | DU30: 12 | DZ30: 35 | EB30: 10 | EG30: 13 | EH30: 10 | EN30: 8 | EP30: 15 | EU30: 25 | EX30: 15 | FB30: 45 | FC30: 60 | FD30: 40 | FE30: 15 | FI30: 35 | FJ30: 10 | FL30: 35 | FP30: 10 | FQ30: 5 | FR30: 30 | FS30: 40 | GM30: 10 | GN30: 25 | GQ30: 25 | GT30: 37 | GX30: 34 | GY30: 32 | GZ30: 10 | HA30: 10 | HM30: 20 | HT30: 27 | HV30: 28 | IC30: 55 | ID30: 11 | IH30: 20 | IK30: 18 | IQ30: 45 | IW30: 27 | IY30: 40 | JC30: 15 | JD30: 10 | JI30: 15 | JK30: 10 | JQ30: 11 | JT30: 19 | JX30: 30 | JZ30: 35 | KG30: 17 | KN30: 15 | KR30: 25 | KS30: 30 | LA30: 55 | LC30: 18 | LF30: 15 | LG30: 10 | LH30: 6 | LN30: 20 | LP30: 15 | LQ30: 40 | LV30: 18 | LX30: 60 | MB30: 40 | MD30: 25 | MI30: 35 | MK30: 20 | MR30: 15 | MV30: 25 | ND30: 25 | NF30: 35
A31: Jarabe Papayas | B31: 7 | E31: 116 | N31: 93 | U31: 107 | AG31: 85 | AL31: 85 | AX31: 69 | BJ31: 84 | BU31: 123 | CP31: 140 | DH31: 119 | DS31: 144 | EM31: 113 | EO31: 57 | EW31: 10 | EX31: 78 | FB31: 52 | FK31: 130 | HA31: 412 | HE31: 225 | IG31: 251 | IW31: 202 | JR31: 248 | KE31: 206 | KT31: 169 | LA31: 133 | LI31: 127 | LU31: 134 | ME31: 199 | MP31: 224
A32: Papayas Confitadas | F32: 41 | O32: 64 | T32: 83 | X32: 39 | AB32: 41 | AF32: 41 | AI32: 33 | AL32: 21 | AP32: 10 | AW32: 58 | BD32: 21 | BG32: 40 | BJ32: 29 | BR32: 41 | BX32: 47 | CF32: 20 | CK32: 46 | CR32: 40 | CS32: 20 | DF32: 19 | DH32: 15 | DL32: 31 | DO32: 35 | DS32: 52 | DY32: 55 | EC32: 26 | EI32: 40 | EN32: 45 | EP32: 86 | EV32: 30 | EW32: 30 | EX32: 20 | FB32: 66 | FE32: 40 | FI32: 43 | FJ32: 30 | FL32: 68 | FO32: 100 | FS32: 28 | FW32: 15 | FY32: 25 | FZ32: 57 | GF32: 50 | GG32: 39 | GL32: 47 | GM32: 50 | GN32: 81 | GQ32: 43 | GS32: 20 | GT32: 50 | GX32: 50 | GZ32: 40 | HB32: 40 | HC32: 35 | HE32: 49 | HG32: 33 | HL32: 50 | HP32: 60 | HU32: 55 | IB32: 57 | II32: 42 | IO32: 57 | IR32: 30 | IV32: 41 | JC32: 64 | JE32: 69 | JK32: 75 | JL32: 50 | JQ32: 28 | JS32: 40 | JW32: 85 | JZ32: 30 | KA32: 50 | KH32: 91 | KM32: 42 | KO32: 70 | KT32: 45 | KV32: 74 | LA32: 30 | LC32: 50 | LF32: 30 | LG32: 21 | LJ32: 33 | LN32: 36 | LO32: 25 | LQ32: 61 | LT32: 33 | LW32: 35 | LX32: 79 | MB32: 20 | ME32: 84 | MI32: 80 | ML32: 83 | MP32: 91 | MS32: 20 | MW32: 41 | MZ32: 72 | NE32: 62
A33: Trozos Confitados | F33: 61 | O33: 17 | T33: 15 | X33: 42 | AB33: 10 | AF33: 9 | AI33: 16 | AL33: 52 | AP33: 54 | AW33: 45 | BD33: 8 | BG33: 22 | BJ33: 13 | BR33: 30 | BX33: 8 | CF33: 19 | CK33: 36 | CS33: 96 | DF33: 26 | DH33: 40 | DL33: 22 | DO33: 9 | DY33: 30 | EI33: 25 | EN33: 27 | EP33: 16 | EV33: 15 | EX33: 5 | FB33: 39 | FE33: 14 | FI33: 10 | FL33: 19 | FO33: 13 | FS33: 5 | FW33: 34 | FZ33: 36 | GG33: 20 | GL33: 21 | GN33: 39 | GQ33: 26 | GT33: 37 | GX33: 15 | HB33: 37 | HE33: 12 | HL33: 14 | HP33: 9 | IB33: 35 | II33: 25 | IO33: 57 | IR33: 37 | IV33: 31 | JC33: 32 | JE33: 33 | JL33: 22 | JS33: 16 | JW33: 18 | KA33: 19 | KH33: 15 | KM33: 39 | KO33: 31 | KT33: 18 | KV33: 44 | LC33: 27 | LG33: 30 | LJ33: 36 | LN33: 10 | LO33: 22 | LT33: 21 | LX33: 35 | MB33: 8 | ME33: 12 | MI33: 28 | ML33: 29 | MP33: 23 | MS33: 21 | MW33: 41 | MZ33: 27 | NE33: 9
A36: rendimiento pelador | B36: =IF(B5=0," ",(B10+B16+B22+B26+B28+B30)/B5) | C36: =IF(C5=0," ",(C10+C16+C22+C26+C28+C30)/C5) | D36: =IF(D5=0," ",(D10+D16+D22+D26+D28+D30)/D5) -> 0.15838509 | E36: =IF(E5=0," ",(E10+E16+E22+E26+E28+E30)/E5) -> 0 | F36: =IF(F5=0," ",(F10+F16+F22+F26+F28+F30)/F5) | G36: =IF(G5=0," ",(G10+G16+G22+G26+G28+G30)/G5) | H36: =IF(H5=0," ",(H10+H16+H22+H26+H28+H30)/H5) | I36: =IF(I5=0," ",(I10+I16+I22+I26+I28+I30)/I5) | ... NI36: =IF(NI5=0," ",(NI10+NI16+NI22+NI26+NI28+NI30)/NI5)
A37: rendimiento nectar kg/lt | B37: =IF(SUM(B11:B14)=0," ",(B9+B10)/(((B11+B12)*0.25)+(B13+B14))) -> 0 | C37: =IF(SUM(C11:C14)=0," ",(C9+C10)/(((C11+C12)*0.25)+(C13+C14))) -> 0.3270646 | D37: =IF(SUM(D11:D14)=0," ",(D9+D10)/(((D11+D12)*0.25)+(D13+D14))) -> 0.34153692 | E37: =IF(SUM(E11:E14)=0," ",(E9+E10)/(((E11+E12)*0.25)+(E13+E14))) -> 0.34482759 | F37: =IF(SUM(F11:F14)=0," ",(F9+F10)/(((F11+F12)*0.25)+(F13+F14))) | G37: =IF(SUM(G11:G14)=0," ",(G9+G10)/(((G11+G12)*0.25)+(G13+G14))) | H37: =IF(SUM(H11:H14)=0," ",(H9+H10)/(((H11+H12)*0.25)+(H13+H14))) | I37: =IF(SUM(I11:I14)=0," ",(I9+I10)/(((I11+I12)*0.25)+(I13+I14))) | ... NI37: =IF(SUM(NI11:NI14)=0," ",(NI9+NI10)/(((NI11+NI12)*0.25)+(NI13+NI14)))
A38: rendimiento papaya al jugo kg/lt | B38: =IF(SUM(B15:B16)=0," ",(B15+B16)/(B17+(B18*0.46)+(B19*0.15)+(B20*0.46))) | C38: =IF(SUM(C15:C16)=0," ",(C15+C16)/(C17+(C18*0.46)+(C19*0.15)+(C20*0.46))) | D38: =IF(SUM(D15:D16)=0," ",(D15+D16)/(D17+(D18*0.46)+(D19*0.15)+(D20*0.46))) | E38: =IF(SUM(E15:E16)=0," ",(E15+E16)/(E17+(E18*0.46)+(E19*0.15)+(E20*0.46))) | F38: =IF(SUM(F15:F16)=0," ",(F15+F16)/(F17+(F18*0.46)+(F19*0.15)+(F20*0.46))) | G38: =IF(SUM(G15:G16)=0," ",(G15+G16)/(G17+(G18*0.46)+(G19*0.15)+(G20*0.46))) | H38: =IF(SUM(H15:H16)=0," ",(H15+H16)/(H17+(H18*0.46)+(H19*0.15)+(H20*0.46))) | I38: =IF(SUM(I15:I16)=0," ",(I15+I16)/(I17+(I18*0.46)+(I19*0.15)+(I20*0.46))) | ... NI38: =IF(SUM(NI15:NI16)=0," ",(NI15+NI16)/(NI17+(NI18*0.46)+(NI19*0.15)+(NI20*0.46)))
A39: rendimiento mermelada kg/lt | B39: =IF(SUM(B21:B22)=0," ",(B21+B22)/(B23+(B24*0.34))) | C39: =IF(SUM(C21:C22)=0," ",(C21+C22)/(C23+(C24*0.34))) | D39: =IF(SUM(D21:D22)=0," ",(D21+D22)/(D23+(D24*0.34))) | E39: =IF(SUM(E21:E22)=0," ",(E21+E22)/(E23+(E24*0.34))) | F39: =IF(SUM(F21:F22)=0," ",(F21+F22)/(F23+(F24*0.34))) | G39: =IF(SUM(G21:G22)=0," ",(G21+G22)/(G23+(G24*0.34))) | H39: =IF(SUM(H21:H22)=0," ",(H21+H22)/(H23+(H24*0.34))) | I39: =IF(SUM(I21:I22)=0," ",(I21+I22)/(I23+(I24*0.34))) | ... NI39: =IF(SUM(NI21:NI22)=0," ",(NI21+NI22)/(NI23+(NI24*0.34)))
A40: rendimiento congelada cubos kg/kg | B40: =IF(SUM(B27:B28)=0," ",(B27+B28)/B29) | C40: =IF(SUM(C27:C28)=0," ",(C27+C28)/C29) | D40: =IF(SUM(D27:D28)=0," ",(D27+D28)/D29) | E40: =IF(SUM(E27:E28)=0," ",(E27+E28)/E29) | F40: =IF(SUM(F27:F28)=0," ",(F27+F28)/F29) | G40: =IF(SUM(G27:G28)=0," ",(G27+G28)/G29) | H40: =IF(SUM(H27:H28)=0," ",(H27+H28)/H29) | I40: =IF(SUM(I27:I28)=0," ",(I27+I28)/I29) | ... JD40: =IF(SUM(JD27:JD28)=0," ",(JD27+JD28)/JD29) | JE40: =IF(SUM(JE27:JE28)=0," ",(JE27+JE28)/#REF!) | JF40: =IF(SUM(JF27:JF28)=0," ",(JF27+JF28)/JF29) | JG40: =IF(SUM(JG27:JG28)=0," ",(JG27+JG28)/JG29) | JH40: =IF(SUM(JH27:JH28)=0," ",(JH27+JH28)/JH29) | JI40: =IF(SUM(JI27:JI28)=0," ",(JI27+JI28)/JI29) | JJ40: =IF(SUM(JJ27:JJ28)=0," ",(JJ27+JJ28)/JJ29) | JK40: =IF(SUM(JK27:JK28)=0," ",(JK27+JK28)/JK29) | JL40: =IF(SUM(JL27:JL28)=0," ",(JL27+JL28)/JL29) | JM40: =IF(SUM(JM27:JM28)=0," ",(JM27+JM28)/JM29) | ... NI40: =IF(SUM(NI27:NI28)=0," ",(NI27+NI28)/NI29)

Sheet Ventas_Des
C1: 1 | D1: 2 | E1: 3 | F1: 4 | G1: 5 | H1: 6 | I1: 7 | J1: 8 | K1: 9 | L1: 10 | M1: 11 | N1: 12 | O1: 13 | P1: 14 | Q1: 15 | R1: 16 | S1: 17 | T1: 18 | U1: 19 | V1: 20 | W1: 21 | X1: 22 | Y1: 23 | Z1: 24 | AA1: 25 | AB1: 26 | AC1: 27 | AD1: 28 | AE1: 29 | AF1: 30 | AG1: 31 | AH1: 32 | AI1: 33 | AJ1: 34 | AK1: 35 | AL1: 36 | AM1: 37 | AN1: 38 | AO1: 39 | AP1: 40 | AQ1: 41 | AR1: 42 | AS1: 43 | AT1: 44 | AU1: 45 | AV1: 46 | AW1: 47 | AX1: 48 | AY1: 49 | AZ1: 50 | BA1: 51 | BB1: 52 | BC1: 53
A2: Fábrica Papayas | C2: Semana 1 | D2: Semana 2 | E2: Semana 3 | F2: Semana 4 | G2: Semana 5 | H2: Semana 6 | I2: Semana 7 | J2: Semana 8 | K2: Semana 9 | L2: Semana 10 | M2: Semana 11 | N2: Semana 12 | O2: Semana 13 | P2: Semana 14 | Q2: Semana 15 | R2: Semana 16 | S2: Semana 17 | T2: Semana 18 | U2: Semana 19 | V2: Semana 20 | W2: Semana 21 | X2: Semana 22 | Y2: Semana 23 | Z2: Semana 24 | AA2: Semana 25 | AB2: Semana 26 | AC2: Semana 27 | AD2: Semana 28 | AE2: Semana 29 | AF2: Semana 30 | AG2: Semana 31 | AH2: Semana 32 | AI2: Semana 33 | AJ2: Semana 34 | AK2: Semana 35 | AL2: Semana 36 | AM2: Semana 37 | AN2: Semana 38 | AO2: Semana 39 | AP2: Semana 40 | AQ2: Semana 41 | AR2: Semana 42 | AS2: Semana 43 | AT2: Semana 44 | AU2: Semana 45 | AV2: Semana 46 | AW2: Semana 47 | AX2: Semana 48 | AY2: Semana 49 | AZ2: Semana 50 | BA2: Semana 51 | BB2: Semana 52 | BC2: Semana 53
A3: Stock Materia prima de huerto (Kgs) | AV3: 214
A4: Materia prima de huerto (Kgs) | P4: 693 | Q4: 429 | R4: 700
A5: Materia prima Elaborada (Kgs) | Q5: 282 | R5: 251 | S5: 483
A6: descarte
A7: venta descarte por calibre | AX7: 441 | BB7: 186
A9: Papaya congelada
A10: Papaya directa
A11: Nectar 250cc | D11: 2835 | E11: 1890 | F11: 2772 | G11: 2250 | H11: 3213 | I11: 2695 | J11: 2961 | K11: 1305 | L11: 2068 | M11: 1260 | N11: 1890 | P11: 1260 | Q11: 72 | R11: 72 | S11: 756 | T11: 630 | U11: 1260 | V11: 630 | W11: 666 | X11: 2128 | Y11: 1332 | Z11: 1368 | AA11: 1089 | AB11: 1059 | AC11: 1056 | AD11: 2034 | AE11: 3618 | AF11: 2313 | AG11: 2277 | AH11: 3897 | AI11: 3897 | AJ11: 1809 | AK11: 2675 | AL11: 2745 | AM11: 1512 | AN11: 4095 | AO11: 2366 | AP11: 2268 | AQ11: 3033 | AR11: 2358 | AS11: 2268 | AT11: 2522 | AU11: 2835 | AV11: 1404 | AW11: 2961 | AX11: 2223 | AY11: 2520 | AZ11: 1404 | BA11: 2925 | BB11: 2385 | BC11: 2236
A12: Nectar 250cc light | C12: 576 | D12: 630 | E12: 630 | F12: 630 | G12: 630 | H12: 189 | I12: 1329 | J12: 72 | K12: 1260 | L12: 981 | U12: 729 | X12: 315 | Y12: 351 | Z12: 441 | AA12: 315 | AB12: 389 | AD12: 630 | AF12: 1260 | AH12: 436 | AI12: 693 | AJ12: 315 | AK12: 315 | AM12: 504 | AN12: 630 | AO12: 1017 | AQ12: 630 | AT12: 945 | AU12: 630 | AV12: 0 | AW12: 504 | AX12: 1134 | AY12: 378 | AZ12: 774 | BB12: 945 | BC12: 1368
A13: Nectar 1 lt | C13: 408 | D13: 1488 | E13: 1644 | F13: 1992 | G13: 1669 | H13: 1797 | I13: 2880 | J13: 2168 | K13: 2573 | L13: 1198 | M13: 840 | N13: 480 | O13: 608 | P13: 480 | Q13: 4 | R13: 540 | S13: 292 | T13: 564 | U13: 812 | V13: 432 | W13: 800 | X13: 1008 | Y13: 882 | Z13: 900 | AA13: 1168 | AB13: 648 | AC13: 556 | AD13: 1320 | AE13: 2016 | AF13: 2688 | AG13: 1582 | AH13: 837 | AI13: 460 | AJ13: 1580 | AK13: 1448 | AL13: 1826 | AM13: 1444 | AN13: 2172 | AO13: 1936 | AP13: 1386 | AQ13: 2452 | AR13: 1608 | AS13: 1160 | AT13: 2220 | AU13: 1060 | AV13: 1008 | AW13: 1444 | AX13: 1068 | AY13: 1564 | AZ13: 1852 | BA13: 848 | BB13: 1500 | BC13: 1806
A14: Nectar 1 lt ligth | C14: 120 | D14: 288 | E14: 492 | F14: 468 | G14: 244 | H14: 336 | I14: 830 | J14: 508 | K14: 720 | L14: 240 | M14: 300 | N14: 24 | R14: 276 | S14: 4 | T14: 72 | U14: 148 | V14: 144 | W14: 360 | X14: 240 | Y14: 36 | Z14: 300 | AA14: 240 | AB14: 240 | AD14: 240 | AE14: 420 | AF14: 624 | AG14: 216 | AH14: 87 | AI14: 192 | AJ14: 378 | AK14: 288 | AL14: 0 | AM14: 288 | AN14: 600 | AO14: 276 | AQ14: 480 | AR14: 290 | AS14: 288 | AT14: 288 | AU14: 288 | AV14: 246 | AW14: 240 | AX14: 648 | AY14: 360 | AZ14: 264 | BA14: 360 | BB14: 504 | BC14: 722
A15: Papaya congelada
A16: Papaya directa
A17: Papaya Jugo 1 Kg | C17: 852 | D17: 456 | E17: 636 | F17: 504 | G17: 576 | H17: 492 | I17: 679 | J17: 540 | K17: 666 | L17: 487 | M17: 456 | N17: 648 | O17: 380 | P17: 504 | Q17: 381 | R17: 585 | S17: 392 | T17: 440 | U17: 536 | V17: 552 | W17: 493 | X17: 624 | Y17: 400 | Z17: 528 | AA17: 636 | AB17: 310 | AC17: 685 | AD17: 654 | AE17: 413 | AF17: 534 | AG17: 448 | AH17: 743 | AI17: 745 | AJ17: 642 | AK17: 656 | AL17: 840 | AM17: 444 | AN17: 576 | AO17: 516 | AP17: 417 | AQ17: 867 | AR17: 455 | AS17: 468 | AT17: 832 | AU17: 296 | AV17: 616 | AW17: 496 | AX17: 688 | AY17: 584 | AZ17: 622 | BA17: 523 | BB17: 480 | BC17: 694
A18: Papaya Jugo 460 grs | D18: 192 | E18: 128 | F18: 64 | G18: 107 | H18: 0 | I18: 0 | N18: 24 | O18: 96 | P18: 172 | Q18: 24 | R18: 48 | S18: 96 | T18: 12 | U18: 98 | V18: 100 | W18: 24 | X18: 192 | Y18: 239 | Z18: 200 | AA18: 152 | AB18: 128 | AC18: 114 | AD18: 112 | AE18: 164 | AF18: 24 | AI18: 60 | AJ18: 176 | AK18: 128 | AL18: 188 | AM18: 128 | AN18: 96 | AO18: 190 | AQ18: 72 | AR18: 79 | AS18: 224 | AT18: 177 | AV18: 64 | AW18: 62 | AX18: 224 | AY18: 128 | AZ18: 392 | BA18: 54 | BB18: 96 | BC18: 123
A19: Papaya Jugo Cubitos 150gr | E19: 316 | F19: 252 | I19: 252 | J19: 441 | K19: 252 | L19: 225 | O19: 189 | U19: 378 | Y19: 126 | Z19: 126 | AB19: 189 | AE19: 252 | AF19: 567 | AG19: 252 | AH19: 504 | AK19: 252 | AM19: 378 | AO19: 315 | AP19: 378 | AR19: 378 | AT19: 509 | AU19: 126 | AV19: 252 | AW19: 252 | AY19: 315 | AZ19: 315 | BA19: 315 | BC19: 4
A20: Papaya Jugo Cubitos 460gr | C20: 129 | D20: 128 | E20: 96 | F20: 384 | G20: 384 | H20: 320 | I20: 368 | J20: 313 | K20: 672 | L20: 647 | N20: 160 | O20: 128 | U20: 192 | X20: 192 | Y20: 192 | AA20: 448 | AB20: 3 | AC20: 322 | AD20: 256 | AE20: 320 | AF20: 486 | AH20: 313 | AI20: 288 | AJ20: 352 | AK20: 128 | AL20: 256 | AM20: 352 | AN20: 512 | AO20: 129 | AP20: 64 | AQ20: 542 | AR20: 246 | AS20: 384 | AT20: 450 | AU20: 128 | AV20: 384 | AW20: 384 | AX20: 188 | AY20: 280 | AZ20: 224 | BA20: 504 | BC20: 505
A21: Papaya congelada
A22: Papaya directa
A23: Mermelada 1 kg | D23: 120 | E23: 240 | F23: 48 | G23: 168 | H23: 242 | I23: 240 | J23: 96 | K23: 242 | L23: 240 | M23: 118 | P23: 120 | S23: 120 | V23: 120 | W23: 240 | AA23: 120 | AB23: 120 | AD23: 192 | AE23: 192 | AG23: 240 | AI23: 193 | AK23: 144 | AL23: 96 | AM23: 120 | AN23: 240 | AO23: 120 | AP23: 72 | AQ23: 188 | AR23: 72 | AS23: 55
A24: MErmelada 340 | C24: 168 | D24: 336 | E24: 228 | F24: 428 | G24: 175 | H24: 385 | I24: 574 | J24: 504 | K24: 280 | L24: 350 | M24: 315 | N24: 175 | P24: 420 | Q24: 24 | R24: 24 | U24: 187 | V24: 175 | W24: 350 | Z24: 315 | AA24: 422 | AB24: 176 | AC24: 283 | AD24: 280 | AE24: 280 | AF24: 398 | AG24: 272 | AH24: 420 | AI24: 214 | AJ24: 341 | AK24: 280 | AL24: 210 | AM24: 210 | AN24: 350 | AO24: 175 | AP24: 175 | AQ24: 539 | AR24: 175 | AS24: 175 | AT24: 385 | AU24: 350 | AV24: 490 | AW24: 316 | AX24: 420 | AY24: 167 | AZ24: 70
A25: Papaya directa
A26: Papaya Congelada Ditzler (Kg) | C26: 610 | D26: 779 | E26: 1055 | F26: 1168 | G26: 1370 | H26: 700 | I26: 1832 | J26: 1593 | K26: 2380 | L26: 2114 | M26: 951 | N26: 1497 | O26: 1200 | P26: 564 | Q26: 400 | R26: 940 | S26: 830 | T26: 510 | U26: 550 | V26: 520 | W26: 500 | X26: 997 | Y26: 90 | Z26: 850 | AA26: 400 | AB26: 338 | AC26: 300 | AD26: 700 | AE26: 770 | AF26: 620 | AG26: 310 | AH26: 696 | AI26: 410 | AJ26: 1377 | AK26: 600 | AL26: 525 | AM26: 916 | AN26: 995 | AO26: 400 | AP26: 1776 | AQ26: 854 | AR26: 320 | AS26: 1264 | AT26: 801 | AU26: 300 | AV26: 686 | AW26: 1376 | AX26: 952 | AY26: 688 | AZ26: 770 | BA26: 1186 | BC26: 856
A27: Papaya congelada
A28: Papaya directa
A29: Papaya Congelada Cubos (Kg)
A30: Papaya Directa Confites
A31: Jarabe Papayas | C31: 116 | D31: 78 | E31: 126 | G31: 78 | H31: 91 | I31: 69 | K31: 84 | M31: 123 | O31: 2 | P31: 140 | Q31: 2 | S31: 115 | U31: 80 | V31: 66 | W31: 111 | Y31: 137 | Z31: 78 | AA31: 80 | AB31: 34 | AC31: 2 | AD31: 0 | AF31: 273 | AG31: 139 | AH31: 156 | AI31: 69 | AK31: 251 | AM31: 2 | AN31: 195 | AO31: 2 | AQ31: 249 | AR31: 117 | AS31: 80 | AT31: 177 | AU31: 2 | AV31: 133 | AW31: 127 | AX31: 117 | AY31: 17 | AZ31: 199 | BA31: 224 | BC31: 1
A32: Papayas Confitadas | C32: 41 | D32: 64 | E32: 83 | F32: 80 | G32: 74 | H32: 31 | I32: 58 | J32: 21 | K32: 69 | L32: 41 | M32: 47 | N32: 20 | O32: 46 | P32: 60 | Q32: 34 | R32: 66 | T32: 52 | U32: 81 | V32: 40 | W32: 131 | X32: 80 | Y32: 106 | Z32: 141 | AA32: 128 | AB32: 97 | AC32: 89 | AD32: 178 | AE32: 113 | AF32: 165 | AG32: 82 | AH32: 110 | AI32: 55 | AJ32: 57 | AK32: 42 | AL32: 87 | AM32: 41 | AN32: 133 | AO32: 125 | AP32: 68 | AQ32: 165 | AR32: 91 | AS32: 112 | AT32: 119 | AU32: 80 | AV32: 84 | AW32: 96 | AX32: 147 | AY32: 104 | AZ32: 167 | BB32: 113 | BC32: 62
A33: Trozos Confitados | C33: 61 | D33: 17 | E33: 15 | F33: 52 | G33: 25 | H33: 106 | I33: 45 | J33: 8 | K33: 35 | L33: 30 | M33: 8 | N33: 19 | O33: 36 | P33: 96 | Q33: 66 | R33: 31 | U33: 30 | V33: 25 | W33: 43 | X33: 20 | Y33: 53 | Z33: 29 | AA33: 18 | AB33: 70 | AC33: 20 | AD33: 60 | AE33: 63 | AF33: 52 | AG33: 12 | AH33: 23 | AJ33: 35 | AK33: 25 | AL33: 94 | AM33: 31 | AN33: 65 | AO33: 22 | AP33: 16 | AQ33: 37 | AR33: 15 | AS33: 70 | AT33: 62 | AU33: 27 | AV33: 66 | AW33: 58 | AX33: 56 | AY33: 20 | AZ33: 57 | BB33: 68 | BC33: 9
A35: papaya guardada congelada
A36: papaya guardada conserva
A38: rendimiento pelador
A39: rendimiento nectar kg/lt
A40: rendimiento papaya al jugo kg/lt
A41: rendimiento mermelada kg/lt
A42: rendimiento congelada cubos kg/kg

Sheet Stock_Real
C1: 1 | D1: 2 | E1: 3 | F1: 4 | G1: 5 | H1: 6 | I1: 7 | J1: 8 | K1: 9 | L1: 10 | M1: 11 | N1: 12 | O1: 13 | P1: 14 | Q1: 15 | R1: 16 | S1: 17 | T1: 18 | U1: 19 | V1: 20 | W1: 21 | X1: 22 | Y1: 23 | Z1: 24 | AA1: 25 | AB1: 26 | AC1: 27 | AD1: 28 | AE1: 29 | AF1: 30 | AG1: 31 | AH1: 32 | AI1: 33 | AJ1: 34 | AK1: 35 | AL1: 36 | AM1: 37 | AN1: 38 | AO1: 39 | AP1: 40 | AQ1: 41 | AR1: 42 | AS1: 43 | AT1: 44 | AU1: 45 | AV1: 46 | AW1: 47 | AX1: 48 | AY1: 49 | AZ1: 50 | BA1: 51 | BB1: 52 | BC1: 53
A2: Fábrica Papayas | C2: Semana 1 | D2: Semana 2 | E2: Semana 3 | F2: Semana 4 | G2: Semana 5 | H2: Semana 6 | I2: Semana 7 | J2: Semana 8 | K2: Semana 9 | L2: Semana 10 | M2: Semana 11 | N2: Semana 12 | O2: Semana 13 | P2: Semana 14 | Q2: Semana 15 | R2: Semana 16 | S2: Semana 17 | T2: Semana 18 | U2: Semana 19 | V2: Semana 20 | W2: Semana 21 | X2: Semana 22 | Y2: Semana 23 | Z2: Semana 24 | AA2: Semana 25 | AB2: Semana 26 | AC2: Semana 27 | AD2: Semana 28 | AE2: Semana 29 | AF2: Semana 30 | AG2: Semana 31 | AH2: Semana 32 | AI2: Semana 33 | AJ2: Semana 34 | AK2: Semana 35 | AL2: Semana 36 | AM2: Semana 37 | AN2: Semana 38 | AO2: Semana 39 | AP2: Semana 40 | AQ2: Semana 41 | AR2: Semana 42 | AS2: Semana 43 | AT2: Semana 44 | AU2: Semana 45 | AV2: Semana 46 | AW2: Semana 47 | AX2: Semana 48 | AY2: Semana 49 | AZ2: Semana 50 | BA2: Semana 51 | BB2: Semana 52 | BC2: Semana 53
A3: Stock Materia prima de huerto (Kgs) | C3: 0 | D3: 90 | E3: 30 | F3: 30 | G3: 602 | H3: 489 | K3: 237 | L3: 483 | M3: 150 | O3: 222 | P3: 131 | Q3: 246 | R3: 257 | S3: 0 | T3: 160 | U3: 240 | V3: 135 | W3: 163 | X3: 19 | Y3: 281 | Z3: 281 | AA3: 330 | AB3: 221 | AC3: 2236 | AD3: 875 | AO3: 1352 | AP3: 1122 | AQ3: 1336 | AR3: 3231 | AS3: 1500 | AT3: 377 | AU3: 1393 | AV3: 628 | AW3: 1426 | AX3: 1404 | AY3: 510 | AZ3: 196 | BA3: 510 | BB3: 707 | BC3: 1029
A4: Materia prima de huerto (Kgs)
A5: Materia prima Elaborada (Kgs)
A6: descarte
A7: venta descarte por calibre
A9: Papaya congelada
A10: Papaya directa
A11: Nectar 250cc | C11: 3122 | D11: 2491 | E11: 1905 | F11: 1984 | G11: 2060 | H11: 1237 | I11: 781 | J11: 1210 | K11: 1669 | L11: 3778 | M11: 2518 | N11: 2992 | O11: 5192 | P11: 3932 | Q11: 3860 | R11: 3788 | S11: 5272 | T11: 4642 | U11: 3382 | V11: 5992 | W11: 5326 | X11: 5477 | Y11: 4377 | Z11: 6142 | AA11: 5053 | AB11: 3994 | AC11: 2938 | AD11: 4220 | AE11: 3555 | AF11: 3922 | AG11: 1645 | AH11: 1564 | AI11: 29 | AJ11: 1116 | AK11: 2720 | AL11: 2238 | AM11: 2961 | AN11: 1449 | AO11: 1337 | AP11: 2511 | AQ11: 2363 | AR11: 1690 | AS11: 4090 | AT11: 3701 | AU11: 4829 | AV11: 5202 | AW11: 2241 | AX11: 4420 | AY11: 1900 | AZ11: 3728 | BA11: 5265 | BB11: 2880 | BC11: 3080
A12: Nectar 250cc light | C12: 900 | D12: 785 | E12: 814 | F12: 852 | G12: 222 | H12: 421 | I12: 21 | J12: 1309 | K12: 289 | L12: 1799 | M12: 1799 | N12: 1799 | O12: 1799 | P12: 1799 | Q12: 1799 | R12: 1799 | S12: 1799 | T12: 1799 | U12: 1070 | V12: 1070 | W12: 1070 | X12: 1751 | Y12: 1400 | Z12: 959 | AA12: 680 | AB12: 291 | AC12: 1636 | AD12: 1006 | AE12: 1006 | AF12: 439 | AG12: 439 | AH12: 699 | AI12: 6 | AJ12: 334 | AK12: 19 | AL12: 1824 | AM12: 2917 | AN12: 2287 | AO12: 1270 | AP12: 1270 | AQ12: 640 | AR12: 1161 | AS12: 1161 | AT12: 1218 | AU12: 588 | AV12: 1658 | AW12: 1154 | AX12: 2156 | AY12: 1778 | AZ12: 1004 | BA12: 3528 | BB12: 2583 | BC12: 1728
A13: Nectar 1 lt | C13: 1963 | D13: 1699 | E13: 1309 | F13: 1010 | G13: 1269 | H13: 710 | I13: 1215 | J13: 422 | K13: 832 | L13: 637 | M13: 762 | N13: 2792 | O13: 2496 | P13: 2823 | Q13: 2819 | R13: 3440 | S13: 3148 | T13: 3604 | U13: 3416 | V13: 3126 | W13: 3693 | X13: 3432 | Y13: 2774 | Z13: 1874 | AA13: 1752 | AB13: 1998 | AC13: 1442 | AD13: 1620 | AE13: 1751 | AF13: 181 | AH13: 0 | AI13: 8 | AJ13: 1192 | AK13: 1767 | AL13: 945 | AM13: 1405 | AN13: 1169 | AO13: 402 | AP13: 1255 | AQ13: 850 | AR13: 672 | AS13: 2003 | AT13: 1063 | AU13: 3 | AW13: 2326 | AX13: 1258 | AY13: 1663 | AZ13: 1300 | BA13: 1914 | BB13: 2852 | BC13: 2034
A14: Nectar 1 lt ligth | C14: 451 | D14: 415 | E14: 588 | F14: 470 | G14: 226 | H14: 176 | I14: 34 | J14: 270 | K14: 356 | L14: 736 | M14: 436 | N14: 812 | O14: 812 | P14: 943 | Q14: 943 | R14: 1067 | S14: 1600 | T14: 1528 | U14: 1380 | V14: 1768 | W14: 1408 | X14: 1564 | Y14: 1528 | Z14: 1228 | AA14: 988 | AB14: 748 | AC14: 1217 | AD14: 977 | AE14: 557 | AF14: 216 | AH14: 0 | AI14: 59 | AJ14: 338 | AK14: 185 | AL14: 670 | AM14: 1052 | AN14: 452 | AO14: 176 | AP14: 1005 | AQ14: 1058 | AR14: 768 | AS14: 480 | AT14: 483 | AU14: 246 | AW14: 396 | AX14: 800 | AY14: 440 | AZ14: 598 | BA14: 1061 | BB14: 939 | BC14: 534
A15: Papaya congelada
A16: Papaya directa
A17: Papaya Jugo 1 Kg | C17: 218 | D17: 321 | E17: 164 | F17: 215 | G17: 53 | H17: 145 | I17: 38 | J17: 246 | K17: 57 | L17: 277 | M17: 756 | N17: 657 | O17: 909 | P17: 1185 | Q17: 1787 | R17: 1660 | S17: 1732 | T17: 1658 | U17: 1286 | V17: 1012 | W17: 702 | X17: 129 | Y17: 289 | Z17: 195 | AA17: 109 | AB17: 260 | AC17: 112 | AD17: 72 | AE17: 5 | AF17: 5 | AG17: 269 | AH17: 166 | AI17: 244 | AJ17: 203 | AK17: 583 | AL17: 455 | AM17: 439 | AN17: 223 | AO17: 180 | AP17: 396 | AQ17: 152 | AR17: 173 | AS17: 308 | AT17: 120 | AU17: 222 | AV17: 237 | AW17: 374 | AX17: 285 | AY17: 308 | AZ17: 166 | BA17: 85 | BB17: 285 | BC17: 332
A18: Papaya Jugo 460 grs | C18: 106 | D18: 43 | E18: 79 | F18: 70 | G18: 0 | N18: 144 | O18: 173 | P18: 81 | Q18: 82 | R18: 143 | S18: 111 | T18: 126 | U18: 159 | V18: 258 | W18: 322 | X18: 178 | Y18: 107 | Z18: 95 | AA18: 136 | AB18: 73 | AC18: 60 | AD18: 163 | AE18: 11 | AF18: 3 | AG18: 3 | AH18: 113 | AI18: 269 | AJ18: 222 | AK18: 291 | AL18: 243 | AM18: 195 | AN18: 144 | AO18: 27 | AP18: 71 | AQ18: 78 | AR18: 208 | AS18: 89 | AT18: 6 | AU18: 64 | AV18: 62 | AW18: 177 | AX18: 96 | AY18: 99 | AZ18: 45 | BA18: 17 | BB18: 25 | BC18: 85
A19: Papaya Jugo Cubitos 150gr | C19: 532 | D19: 863 | E19: 547 | F19: 295 | G19: 295 | H19: 295 | I19: 486 | J19: 286 | K19: 225 | L19: 533 | M19: 1099 | N19: 1099 | O19: 910 | P19: 910 | Q19: 910 | R19: 1215 | S19: 1215 | T19: 1215 | U19: 1224 | V19: 1224 | W19: 1224 | X19: 1531 | Y19: 1405 | Z19: 1279 | AA19: 1279 | AB19: 1606 | AC19: 1606 | AD19: 1606 | AE19: 1354 | AF19: 787 | AG19: 535 | AH19: 31 | AI19: 31 | AJ19: 840 | AK19: 588 | AL19: 588 | AM19: 1033 | AN19: 1033 | AO19: 718 | AP19: 340 | AQ19: 551 | AR19: 616 | AS19: 616 | AT19: 920 | AU19: 794 | AV19: 678 | AW19: 426 | AX19: 426 | AY19: 993 | AZ19: 678 | BA19: 1263 | BB19: 1263 | BC19: 1259
A20: Papaya Jugo Cubitos 460gr | C20: 234 | D20: 298 | E20: 279 | F20: 131 | G20: 5 | H20: 6 | I20: 154 | J20: 284 | K20: 314 | L20: 251 | M20: 576 | N20: 640 | O20: 512 | P20: 981 | Q20: 981 | R20: 1391 | S20: 1437 | T20: 1437 | U20: 1455 | V20: 1455 | W20: 1455 | X20: 1689 | Y20: 1497 | Z20: 1497 | AA20: 1049 | AB20: 1384 | AC20: 1062 | AD20: 806 | AE20: 486 | AH20: 157 | AI20: 22 | AJ20: 142 | AK20: 455 | AL20: 472 | AM20: 705 | AN20: 193 | AO20: 64 | AP20: 544 | AQ20: 213 | AR20: 391 | AS20: 231 | AT20: 395 | AU20: 267 | AV20: 572 | AW20: 188 | AX20: 702 | AY20: 918 | AZ20: 694 | BA20: 496 | BB20: 801 | BC20: 296
A21: Papaya congelada
A22: Papaya directa
A23: Mermelada 1 kg | C23: 340 | D23: 220 | E23: 220 | F23: 172 | G23: 488 | H23: 246 | I23: 6 | J23: 56 | K23: 250 | L23: 121 | M23: 240 | N23: 240 | O23: 607 | P23: 624 | Q23: 1017 | R23: 1017 | S23: 1152 | T23: 1279 | U23: 1406 | V23: 1286 | W23: 1046 | X23: 1158 | Y23: 1300 | Z23: 1300 | AA23: 1180 | AB23: 1060 | AC23: 1060 | AD23: 868 | AE23: 676 | AF23: 676 | AG23: 436 | AH23: 436 | AI23: 243 | AJ23: 243 | AK23: 99 | AL23: 195 | AM23: 75 | AN23: 256 | AO23: 136 | AP23: 315 | AQ23: 127 | AR23: 55 | AS23: 0 | AX23: 0 | AY23: 5 | AZ23: 5 | BA23: 5 | BB23: 5 | BC23: 321
A24: MErmelada 340 | C24: 1414 | D24: 1078 | E24: 850 | F24: 422 | G24: 1088 | H24: 703 | I24: 129 | K24: 350 | L24: 363 | M24: 665 | N24: 490 | O24: 1304 | P24: 884 | Q24: 860 | R24: 1829 | S24: 2176 | T24: 2530 | U24: 2697 | V24: 2522 | W24: 2172 | X24: 2172 | Y24: 2172 | Z24: 1857 | AA24: 1435 | AB24: 1259 | AC24: 976 | AD24: 696 | AE24: 751 | AF24: 353 | AG24: 453 | AH24: 382 | AI24: 168 | AJ24: 910 | AK24: 630 | AL24: 1129 | AM24: 919 | AN24: 592 | AO24: 417 | AP24: 1327 | AQ24: 788 | AR24: 613 | AS24: 1318 | AT24: 933 | AU24: 583 | AV24: 903 | AW24: 587 | AX24: 167 | AY24: 73 | AZ24: 3 | BA24: 3 | BB24: 36 | BC24: 635
A25: Papaya directa
A26: Papaya Congelada Ditzler (Kg) | C26: 21673 | D26: 21137 | E26: 20252 | F26: 19285 | G26: 17925 | H26: 17279 | I26: 15549 | J26: 14195 | K26: 11897 | L26: 10008 | M26: 9445 | N26: 8189 | O26: 7259 | P26: 7085 | Q26: 7164 | R26: 6704 | S26: 6208 | T26: 6593 | U26: 5240 | V26: 4974 | W26: 4704 | X26: 3715 | Y26: 3849 | Z26: 3218 | AA26: 3243 | AB26: 3083 | AC26: 3333 | AD26: 3198 | AE26: 2697 | AF26: 2343 | AG26: 2487 | AH26: 2527 | AI26: 2910 | AJ26: 2388 | AK26: 2505 | AL26: 3086 | AM26: 3878 | AN26: 3847 | AO26: 5499 | AP26: 4900 | AQ26: 5059 | AR26: 5402 | AS26: 5646 | AT26: 6270 | AU26: 6734 | AV26: 7176 | AW26: 6858 | AX26: 7103 | AY26: 7737 | AZ26: 7824 | BA26: 7188 | BB26: 8076 | BC26: 8107
A27: Papaya congelada
A28: Papaya directa
A29: Papaya Congelada Cubos (Kg)
A30: Papaya Directa Confites
A31: Jarabe Papayas | C31: 7 | D31: 22 | E31: 3 | F31: 3 | G31: 10 | H31: 4 | I31: 4 | J31: 4 | K31: 4 | L31: 4 | M31: 4 | N31: 4 | O31: 2 | P31: 2 | Q31: 0 | R31: 119 | S31: 4 | T31: 148 | U31: 68 | V31: 2 | W31: 61 | X31: 149 | Y31: 64 | Z31: 116 | AA31: 36 | AB31: 2 | AF31: 139 | AG31: 225 | AH31: 69 | AM31: 200 | AN31: 5 | AO31: 3 | AP31: 251 | AQ31: 2 | AR31: 91 | AS31: 11 | AT31: 3 | AU31: 133 | AV31: 127 | AW31: 0 | AX31: 17 | AY31: 199 | AZ31: 0 | BA31: 0 | BB31: 1 | BC31: 0
A32: Papayas Confitadas | AL32: 0
A33: Trozos Confitados | AL33: 0
A35: papaya guardada congelada
A36: papaya guardada conserva
A38: rendimiento pelador
A39: rendimiento nectar kg/lt
A40: rendimiento papaya al jugo kg/lt
A41: rendimiento mermelada kg/lt
A42: rendimiento congelada cubos kg/kg

Sheet Produccion_2026
